#!/usr/bin/env python3
"""
–ë—ã—Å—Ç—Ä—ã–π —Å–∫—Ä–∏–ø—Ç –¥–ª—è —Ç–µ—Å—Ç–∏—Ä–æ–≤–∞–Ω–∏—è email –∏ 2FA
"""

import os
import sys
import django
import asyncio

# –ù–∞—Å—Ç—Ä–æ–π–∫–∞ Django
os.environ.setdefault('DJANGO_SETTINGS_MODULE', 'instagram_uploader.settings')
django.setup()

from uploader.tests_email_2fa import Email2FATestCase, EmailServerTestSuite


async def quick_test():
    """–ë—ã—Å—Ç—Ä—ã–π —Ç–µ—Å—Ç –æ—Å–Ω–æ–≤–Ω—ã—Ö —Ñ—É–Ω–∫—Ü–∏–π"""
    print("[START] QUICK EMAIL AND 2FA TEST")
    print("=" * 50)
    
    # –°–æ–∑–¥–∞–µ–º —Ç–µ—Å—Ç–æ–≤—ã–π —ç–∫–∑–µ–º–ø–ª—è—Ä
    test_case = Email2FATestCase()
    test_case.setUp()
    
    # –ü–æ–ª—É—á–∞–µ–º –∞–∫–∫–∞—É–Ω—Ç—ã —Å email
    from uploader.models import InstagramAccount
    from asgiref.sync import sync_to_async
    
    accounts_with_email = await sync_to_async(list)(
        InstagramAccount.objects.filter(
            email_username__isnull=False,
            email_password__isnull=False
        ).exclude(email_username="", email_password="")
    )
    
    if not accounts_with_email:
        print("[FAIL] No accounts with email found")
        return
    
    print(f"üìß Found {len(accounts_with_email)} accounts with email")
    
    # –¢–µ—Å—Ç–∏—Ä—É–µ–º –ø–µ—Ä–≤—ã–µ 3 –∞–∫–∫–∞—É–Ω—Ç–∞
    test_accounts = accounts_with_email[:3]
    
    for i, account in enumerate(test_accounts, 1):
        print(f"\n[SEARCH] Testing account {i}/{len(test_accounts)}: {account.username}")
        print(f"   Email: {account.email_username}")
        
        # –¢–µ—Å—Ç –ø–æ–¥–∫–ª—é—á–µ–Ω–∏—è –∫ –ø–æ—á—Ç–µ
        email_result = await test_case.test_email_connection_async(account)
        
        # –¢–µ—Å—Ç 2FA –µ—Å–ª–∏ –µ—Å—Ç—å
        if account.tfa_secret:
            tfa_result = await test_case.test_2fa_api_async(account)
        
        await asyncio.sleep(1)
    
    print("\n[OK] Quick test completed!")


if __name__ == "__main__":
    try:
        asyncio.run(quick_test())
    except KeyboardInterrupt:
        print("\n‚èπÔ∏è Test interrupted by user")
    except Exception as e:
        print(f"\n[FAIL] Error: {str(e)}")
        import traceback
        traceback.print_exc() 